Workbook

Sheet U1_comp
A1: ='U1'!A1 -> REGRESSOR | B1: ='U1'!B1 -> COEFFICIENT | D1: =U1_orig!A1 -> REGRESSOR | E1: =U1_orig!B1 -> COEFFICIENT | G1: comp
A2: ='U1'!A2 -> eduSampleFlag | B2: ='U1'!B2 -> -0.32653155 | D2: =U1_orig!A2 -> Ded | E2: =U1_orig!B2 -> -0.32653155 | G2: =B2-E2 -> -8.3266727e-16
A3: ='U1'!A3 -> demMaleFlag | B3: ='U1'!B3 -> 0.022031232 | D3: =U1_orig!A3 -> Dgn | E3: =U1_orig!B3 -> 0.022031232 | G3: =B3-E3 -> 0
A4: ='U1'!A4 -> demAge | B4: ='U1'!B4 -> 0.031052981 | D4: =U1_orig!A4 -> Dag | E4: =U1_orig!B4 -> 0.031052981 | G4: =B4-E4 -> -4.6490589e-16
A5: ='U1'!A5 -> demAgeSq | B5: ='U1'!B5 -> -0.0005674011 | D5: =U1_orig!A5 -> Dag_sq | E5: =U1_orig!B5 -> -0.0005674011 | G5: =B5-E5 -> 5.3125906e-18
A6: ='U1'!A6 -> demNChildL1 | B6: ='U1'!B6 -> -0.00057938553 | D6: =U1_orig!A6 -> Dnc_L1 | E6: =U1_orig!B6 -> -0.00057938553 | G6: =B6-E6 -> 1.2533377e-16
A7: ='U1'!A7 -> demNChild0to2L1 | B7: ='U1'!B7 -> 0.10180174 | D7: =U1_orig!A7 -> Dnc02_L1 | E7: =U1_orig!B7 -> 0.10180174 | G7: =B7-E7 -> -2.0816682e-16
A8: ='U1'!A8 -> yHhQuintilesMonthC5Q2L1 | B8: ='U1'!B8 -> -0.082073094 | D8: =U1_orig!A8 -> Ydses_c5_Q2_L1 | E8: =U1_orig!B8 -> -0.082073094 | G8: =B8-E8 -> -1.3877788e-15
A9: ='U1'!A9 -> yHhQuintilesMonthC5Q3L1 | B9: ='U1'!B9 -> -0.035287234 | D9: =U1_orig!A9 -> Ydses_c5_Q3_L1 | E9: =U1_orig!B9 -> -0.035287234 | G9: =B9-E9 -> -1.8526847e-15
A10: ='U1'!A10 -> yHhQuintilesMonthC5Q4L1 | B10: ='U1'!B10 -> -0.012139572 | D10: =U1_orig!A10 -> Ydses_c5_Q4_L1 | E10: =U1_orig!B10 -> -0.012139572 | G10: =B10-E10 -> -1.8023777e-15
A11: ='U1'!A11 -> yHhQuintilesMonthC5Q5L1 | B11: ='U1'!B11 -> 0.10641117 | D11: =U1_orig!A11 -> Ydses_c5_Q5_L1 | E11: =U1_orig!B11 -> 0.10641117 | G11: =B11-E11 -> -1.3600232e-15
A12: ='U1'!A12 -> eduSampleFlag_demMaleFlag | B12: ='U1'!B12 -> 0.25119503 | D12: =U1_orig!A12 -> Ded_Dgn | E12: =U1_orig!B12 -> 0.25119503 | G12: =B12-E12 -> 0
A13: ='U1'!A13 -> eduSampleFlag_demNChildL1 | B13: ='U1'!B13 -> -0.11591726 | D13: =U1_orig!A13 -> Ded_Dnc_L1_ | E13: =U1_orig!B13 -> -0.11591726 | G13: =B13-E13 -> -1.6653345e-16
... A46: ='U1'!A46 -> Constant | B46: ='U1'!B46 -> -2.2283075 | D46: =U1_orig!A46 -> Constant | E46: =U1_orig!B46 -> -2.2283075 | G46: =B46-E46 -> 1.7763568e-14

Sheet U2_comp
A1: ='U2'!A1 -> REGRESSOR | B1: ='U2'!B1 -> COEFFICIENT | D1: =U2_orig!A1 -> REGRESSOR | E1: =U2_orig!B1 -> COEFFICIENT | G1: comp
A2: ='U2'!A2 -> eduSampleFlag | B2: ='U2'!B2 -> -0.18822354 | D2: =U2_orig!A2 -> Ded | E2: =U2_orig!B2 -> -0.18822354 | G2: =B2-E2 -> 0
A3: ='U2'!A3 -> demAge | B3: ='U2'!B3 -> -0.047256376 | D3: =U2_orig!A3 -> Dag | E3: =U2_orig!B3 -> -0.047256376 | G3: =B3-E3 -> 5.0653925e-16
A4: ='U2'!A4 -> demAgeSq | B4: ='U2'!B4 -> 0.00038201415 | D4: =U2_orig!A4 -> Dag_sq | E4: =U2_orig!B4 -> 0.00038201415 | G4: =B4-E4 -> -4.98733e-18
A5: ='U2'!A5 -> eduHighestC4NaL1 | B5: ='U2'!B5 -> -0.30605667 | D5: =U2_orig!A5 -> Deh_c4_Na_L1 | E5: =U2_orig!B5 -> -0.30605667 | G5: =B5-E5 -> 2.3869795e-15
A6: ='U2'!A6 -> eduHighestC4LowL1 | B6: ='U2'!B6 -> 0.064428268 | D6: =U2_orig!A6 -> Deh_c4_Low_L1 | E6: =U2_orig!B6 -> 0.064428268 | G6: =B6-E6 -> 7.2164497e-16
A7: ='U2'!A7 -> eduHighestC4MediumL1 | B7: ='U2'!B7 -> 0.0765794 | D7: =U2_orig!A7 -> Deh_c4_Medium_L1 | E7: =U2_orig!B7 -> 0.0765794 | G7: =B7-E7 -> 4.4408921e-16
A8: ='U2'!A8 -> eduHighestPartnerC3MediumL1 | B8: ='U2'!B8 -> 0.24482281 | D8: =U2_orig!A8 -> Dehsp_c3_Medium_L1 | E8: =U2_orig!B8 -> 0.24482281 | G8: =B8-E8 -> 4.4408921e-16
A9: ='U2'!A9 -> eduHighestPartnerC3LowL1 | B9: ='U2'!B9 -> 0.27635231 | D9: =U2_orig!A9 -> Dehsp_c3_Low_L1 | E9: =U2_orig!B9 -> 0.27635231 | G9: =B9-E9 -> 5.5511151e-16
A10: ='U2'!A10 -> healthSelfRatedFairL1 | B10: ='U2'!B10 -> 0.1449211 | D10: =U2_orig!A10 -> Dhe_Fair_L1 | E10: =U2_orig!B10 -> 0.1449211 | G10: =B10-E10 -> -5.2735594e-16
A11: ='U2'!A11 -> healthSelfRatedGoodL1 | B11: ='U2'!B11 -> 0.17396464 | D11: =U2_orig!A11 -> Dhe_Good_L1 | E11: =U2_orig!B11 -> 0.17396464 | G11: =B11-E11 -> -1.7208457e-15
A12: ='U2'!A12 -> healthSelfRatedVeryGoodL1 | B12: ='U2'!B12 -> 0.21576151 | D12: =U2_orig!A12 -> Dhe_VeryGood_L1 | E12: =U2_orig!B12 -> 0.21576151 | G12: =B12-E12 -> -2.4147351e-15
A13: ='U2'!A13 -> healthSelfRatedExcellentL1 | B13: ='U2'!B13 -> 0.2527093 | D13: =U2_orig!A13 -> Dhe_Excellent_L1 | E13: =U2_orig!B13 -> 0.2527093 | G13: =B13-E13 -> -2.7200464e-15
... A45: ='U2'!A45 -> Constant | B45: ='U2'!B45 -> 0.36336029 | D45: =U2_orig!A45 -> Constant | E45: =U2_orig!B45 -> 0.36336029 | G45: =B45-E45 -> -3.0475622e-14

Sheet Info
A1: Description: | B1: Model parameters for relationship status projection
A2: Authors: | B2: Patryk Bronka, Justin van de Ven, Daria Popova, Aleksandra Kolndrekaj, Ashley Burdett
A3: Last edit: 15 April 2026 (DP)
A5: Process: | B5: Description:
A6: U1 | B6: Prob enter partnership
A7: U2 | B7: Prob exit partnership
A10: Notes: | B10: Estimation sample: UK_ipop.dta with grossing up weight dwt
B11: Conditions for processes are defined as globals in master.do
B12: Combined former processes U1a and U1b

Sheet Gof
A1: Goodness of fit
A3: U1 - Form partnership
A4: Pseudo R-squared | B4: 0.10167353 | E4: Chi^2 | F4: 942.07545
A5: N | B5: 125044 | E5: Log likelihood | F5: -7281512.5
A7: U2 - End partnership
A8: Pseudo R-squared | B8: 0.12641418 | E8: Chi^2 | F8: 1215.5183
A9: N | B9: 106189 | E9: Log likelihood | F9: -4466906.2

Sheet U1_orig
A1: REGRESSOR | B1: COEFFICIENT | C1: Ded | D1: Dgn | E1: Dag | F1: Dag_sq | G1: Dnc_L1 | H1: Dnc02_L1 | I1: Ydses_c5_Q2_L1 | J1: Ydses_c5_Q3_L1 | K1: Ydses_c5_Q4_L1 | L1: Ydses_c5_Q5_L1 | M1: Ded_Dgn | N1: Ded_Dnc_L1_ | O1: Ded_Dnc02_L1 | P1: Ded_Ydses_c5_Q2_L1 | Q1: Ded_Ydses_c5_Q3_L1 | R1: Ded_Ydses_c5_Q4_L1 | S1: Ded_Ydses_c5_Q5_L1 | T1: Deh_c4_High | U1: Deh_c4_Medium | V1: Les_c4_Student_L1 | W1: Les_c4_NotEmployed_L1 | X1: Les_c4_Retired_L1 | Y1: Les_c4_Student_Dgn_L1 | Z1: Les_c4_NotEmployed_Dgn_L1 | AA1: Les_c4_Retired_Dgn_L1 | AB1: Dhe_pcs_L1 | AC1: Dhe_mcs_L1 | AD1: demRgnUKC | AE1: demRgnUKD | AF1: demRgnUKE | AG1: demRgnUKF | AH1: demRgnUKG | AI1: demRgnUKH | AJ1: demRgnUKJ | AK1: demRgnUKK | AL1: demRgnUKL | AM1: demRgnUKM | AN1: demRgnUKN | AO1: Year_transformed | AP1: Y2020 | AQ1: Y2021 | AR1: demEthnC4Asian | AS1: demEthnC4Black | AT1: demEthnC4Other | AU1: Constant
A2: Ded | B2: -0.32653155 | C2: 0.022120545 | D2: 0.00031805057 | E2: 9.0673993e-05 | F2: -1.0070022e-06 | G2: 0.00018046448 | H2: -2.8366006e-05 | I2: 0.00061920924 | J2: 0.00028422119 | K2: 0.00059041247 | L2: 0.00042040336 | M2: -0.0061359492 | N2: -0.0056156104 | O2: -0.0018677534 | P2: -0.015137141 | Q2: -0.0098032047 | R2: -0.015810559 | S2: -0.0051891541 | T2: 0.0019436598 | U2: 0.0019151458 | V2: -0.0023403046 | W2: 0.00099997364 | X2: 0.0013051876 | Y2: 0.0028725921 | Z2: -0.00022638964 | AA2: -0.00033171819 | AB2: -7.7079369e-06 | AC2: 7.2758599e-08 | AD2: -0.00014390658 | AE2: -2.8564721e-05 | AF2: -5.5780428e-05 | AG2: -0.00011398151 | AH2: 0.00015761292 | AI2: 2.5996757e-05 | AJ2: 0.00058236727 | AK2: -8.2699773e-05 | AL2: -0.00050106306 | AM2: -0.00013507363 | AN2: 0.00012565942 | AO2: 8.6155511e-06 | AP2: -7.0367987e-05 | AQ2: -3.2984526e-05 | AR2: -0.00019976217 | AS2: 0.00093400101 | AT2: -0.00029281012 | AU2: -0.0041629364
A3: Dgn | B3: 0.022031232 | C3: 0.00031805057 | D3: 0.00091918944 | E3: 5.2566515e-06 | F3: -2.0498773e-08 | G3: 9.6728785e-05 | H3: -3.5872067e-05 | I3: 2.9119515e-05 | J3: -7.8166952e-05 | K3: -9.8187629e-05 | L3: -0.00013777469 | M3: -1.8559357e-05 | N3: -0.00010111487 | O3: 5.2385963e-05 | P3: -1.6986439e-05 | Q3: 8.324256e-05 | R3: 9.7554909e-05 | S3: 0.00012058235 | T3: 0.00039443283 | U3: 0.00020796098 | V3: 0.00040646992 | W3: 0.00042443365 | X3: 0.00038439503 | Y3: -0.00091032799 | Z3: -0.00086469719 | AA3: -0.00090664118 | AB3: 1.9802191e-06 | AC3: 2.6256133e-06 | AD3: -0.00012369198 | AE3: -3.7715059e-05 | AF3: -5.9915341e-05 | AG3: -5.9244339e-05 | AH3: -2.6828693e-05 | AI3: -0.00011245049 | AJ3: -0.00012869516 | AK3: -3.80687e-05 | AL3: -5.9252026e-06 | AM3: -0.00022940907 | AN3: -9.7870477e-05 | AO3: 1.4920262e-06 | AP3: 3.079314e-05 | AQ3: 5.7561717e-05 | AR3: -6.5745389e-05 | AS3: -7.4825504e-06 | AT3: -0.00020955188 | AU3: -0.0009737044
A4: Dag | B4: 0.031052981 | C4: 9.0673993e-05 | D4: 5.2566515e-06 | E4: 3.1938768e-05 | F4: -3.9865157e-07 | G4: -6.6460658e-06 | H4: 1.2431699e-05 | I4: 4.0973435e-05 | J4: 4.2632714e-05 | K4: 4.966429e-05 | L4: 3.3397641e-05 | M4: 3.4310766e-05 | N4: -7.6821371e-06 | O4: 1.2715653e-05 | P4: -9.916009e-05 | Q4: -6.8564221e-05 | R4: -7.0986113e-05 | S4: -5.66922e-05 | T4: 1.4085399e-05 | U4: 3.4165599e-05 | V4: 0.00010917283 | W4: 7.1829224e-05 | X4: 0.00030958339 | Y4: 1.1829265e-05 | Z4: -5.8527936e-06 | AA4: -8.0067008e-05 | AB4: 6.2778453e-07 | AC4: 6.6394116e-08 | AD4: -4.0932221e-05 | AE4: 8.1417109e-06 | AF4: 1.083561e-05 | AG4: 5.4424427e-06 | AH4: 1.8764822e-05 | AI4: -1.4786838e-05 | AJ4: 2.2945529e-05 | AK4: 1.7827662e-05 | AL4: -2.3727468e-05 | AM4: 3.3322105e-05 | AN4: 2.4128471e-05 | AO4: 1.7337031e-06 | AP4: -4.5125372e-06 | AQ4: -2.6286666e-05 | AR4: -3.3731695e-06 | AS4: -2.2089806e-05 | AT4: 4.9469772e-05 | AU4: -0.00071802051
A5: Dag_sq | B5: -0.0005674011 | C5: -1.0070022e-06 | D5: -2.0498773e-08 | E5: -3.9865157e-07 | F5: 5.1676039e-09 | G5: 1.013915e-07 | H5: -1.1036609e-07 | I5: -4.7591378e-07 | J5: -5.1324166e-07 | K5: -6.7104715e-07 | L5: -5.0161281e-07 | M5: -4.1108093e-07 | N5: 5.4952139e-08 | O5: -2.0246041e-07 | P5: 1.1480227e-06 | Q5: 8.1458452e-07 | R5: 8.8430769e-07 | S5: 7.4359265e-07 | T5: -1.2285366e-07 | U5: -3.3766934e-07 | V5: -1.1763224e-06 | W5: -8.5381969e-07 | X5: -4.4206417e-06 | Y5: -1.6980182e-07 | Z5: 8.8332328e-08 | AA5: 1.0294289e-06 | AB5: -1.7343914e-09 | AC5: 4.9532923e-10 | AD5: 4.0315398e-07 | AE5: -1.4511933e-07 | AF5: -1.3338915e-07 | AG5: -8.2971252e-08 | AH5: -2.0507833e-07 | AI5: 2.1943885e-07 | AJ5: -2.9718368e-07 | AK5: -2.0237247e-07 | AL5: 4.7119598e-07 | AM5: -4.8539976e-07 | AN5: -2.7137905e-07 | AO5: -2.2496086e-08 | AP5: 1.0355352e-07 | AQ5: 2.6619799e-07 | AR5: 1.1846346e-07 | AS5: 2.0514295e-07 | AT5: -7.0303385e-07 | AU5: 8.2210759e-06
A6: Dnc_L1 | B6: -0.00057938553 | C6: 0.00018046448 | D6: 9.6728785e-05 | E6: -6.6460658e-06 | F6: 1.013915e-07 | G6: 0.00031831358 | H6: -0.00053739877 | I6: -5.232067e-05 | J6: -6.1433537e-05 | K6: 1.8367624e-05 | L6: 4.3011823e-05 | M6: -1.6492524e-05 | N6: -0.00031030463 | O6: 0.00053609105 | P6: 7.2557258e-05 | Q6: 6.4512225e-05 | R6: -1.0180196e-05 | S6: -3.9197131e-05 | T6: 7.0594962e-05 | U6: 5.8648136e-05 | V6: 6.6987425e-06 | W6: 1.6031272e-05 | X6: 5.5154432e-05 | Y6: -9.5460542e-05 | Z6: -6.1886474e-05 | AA6: -9.2447399e-05 | AB6: -5.4147812e-07 | AC6: 3.8389547e-08 | AD6: 6.7907952e-06 | AE6: 4.4614118e-05 | AF6: 3.269575e-05 | AG6: 5.032305e-05 | AH6: 3.305206e-06 | AI6: 2.1044895e-05 | AJ6: 1.5742576e-05 | AK6: 4.6893055e-05 | AL6: 1.6328994e-05 | AM6: -3.335231e-05 | AN6: -3.5791927e-05 | AO6: -2.9155323e-06 | AP6: -2.415156e-05 | AQ6: 6.3062338e-05 | AR6: -2.5981278e-05 | AS6: -5.6910292e-05 | AT6: -0.00014292045 | AU6: -3.8924888e-05
A7: Dnc02_L1 | B7: 0.10180174 | C7: -2.8366006e-05 | D7: -3.5872067e-05 | E7: 1.2431699e-05 | F7: -1.1036609e-07 | G7: -0.00053739877 | H7: 0.0033599961 | I7: 0.00015915559 | J7: 0.00031050228 | K7: 0.00021122026 | L7: 0.00019159426 | M7: 2.6692387e-05 | N7: 0.00052242506 | O7: -0.0033597475 | P7: -0.0001766442 | Q7: -0.00033201247 | R7: -0.00022423216 | S7: -0.0002791401 | T7: 2.5605107e-05 | U7: -4.7946933e-05 | V7: 0.00026553607 | W7: -0.00025060276 | X7: -9.5085599e-05 | Y7: 6.8059694e-05 | Z7: 0.00060656481 | AA7: 3.8639042e-05 | AB7: -3.5421064e-06 | AC7: -2.0375662e-06 | AD7: 7.1089864e-05 | AE7: -1.1558806e-05 | AF7: 0.00017966872 | AG7: -0.00011724068 | AH7: 0.00027625644 | AI7: 0.00015776281 | AJ7: 5.0235387e-05 | AK7: 6.7752955e-05 | AL7: 0.00012421664 | AM7: 0.0001628578 | AN7: 2.7816442e-05 | AO7: -5.5839704e-06 | AP7: 0.00030078104 | AQ7: -2.7848104e-05 | AR7: 1.925751e-05 | AS7: -3.8229327e-05 | AT7: -2.0472481e-05 | AU7: -0.00013024887
A8: Ydses_c5_Q2_L1 | B8: -0.082073094 | C8: 0.00061920924 | D8: 2.9119515e-05 | E8: 4.0973435e-05 | F8: -4.7591378e-07 | G8: -5.232067e-05 | H8: 0.00015915559 | I8: 0.0025521847 | J8: 0.0021183025 | K8: 0.0020878058 | L8: 0.0019657042 | M8: 0.00013754961 | N8: 6.1381435e-05 | O8: -0.00013798332 | P8: -0.0025589498 | Q8: -0.0020963129 | R8: -0.0019914254 | S8: -0.001968976 | T8: -0.00012373296 | U8: -0.00017378026 | V8: 0.0015341079 | W8: 0.001478136 | X8: 0.00059190859 | Y8: -0.00017442095 | Z8: 0.00016339479 | AA8: -0.00024524295 | AB8: -4.5759165e-06 | AC8: -5.8470815e-07 | AD8: -5.3216888e-05 | AE8: 0.00016165516 | AF8: -5.8312048e-05 | AG8: -0.00031503401 | AH8: 7.2434037e-05 | AI8: -1.5067285e-05 | AJ8: 9.9211914e-05 | AK8: -9.7982037e-05 | AL8: -0.00019147226 | AM8: -5.9455414e-06 | AN8: 9.654825e-05 | AO8: 8.7115984e-06 | AP8: 0.00013163899 | AQ8: -0.00029121168 | AR8: 5.0245198e-05 | AS8: -1.6893054e-05 | AT8: 0.0002279893 | AU8: -0.0026203578
A9: Ydses_c5_Q3_L1 | B9: -0.035287234 | C9: 0.00028422119 | D9: -7.8166952e-05 | E9: 4.2632714e-05 | F9: -5.1324166e-07 | G9: -6.1433537e-05 | H9: 0.00031050228 | I9: 0.0021183025 | J9: 0.0032940066 | K9: 0.0026170018 | L9: 0.0024810878 | M9: 1.7495161e-05 | N9: 7.8562495e-05 | O9: -0.0002722754 | P9: -0.0021339881 | Q9: -0.0032789688 | R9: -0.0025032394 | S9: -0.0025034082 | T9: -0.00060037113 | U9: -0.0006637542 | V9: 0.0018994009 | W9: 0.0018959744 | X9: 0.00084964813 | Y9: 6.311371e-05 | Z9: 0.00024280861 | AA9: -0.00032576536 | AB9: -3.3645144e-06 | AC9: -2.350867e-06 | AD9: 0.00022979942 | AE9: 0.00035440835 | AF9: 4.3131043e-06 | AG9: -0.00021505991 | AH9: 0.00018763252 | AI9: 3.5850996e-05 | AJ9: 0.00013011618 | AK9: 4.8637504e-06 | AL9: 0.00012337431 | AM9: 0.00010738078 | AN9: 0.00015687387 | AO9: 2.5794233e-05 | AP9: 6.2036958e-05 | AQ9: -0.000375827 | AR9: 0.00010056824 | AS9: -2.9270166e-05 | AT9: 0.00033027949 | AU9: -0.0030383983
A10: Ydses_c5_Q4_L1 | B10: -0.012139572 | C10: 0.00059041247 | D10: -9.8187629e-05 | E10: 4.966429e-05 | F10: -6.7104715e-07 | G10: 1.8367624e-05 | H10: 0.00021122026 | I10: 0.0020878058 | J10: 0.0026170018 | K10: 0.003186341 | L10: 0.0025261357 | M10: 1.0763959e-05 | N10: 2.0442678e-05 | O10: -0.00024333002 | P10: -0.0020538256 | Q10: -0.0025455577 | R10: -0.0030140641 | S10: -0.0024939893 | T10: -0.00032152296 | U10: -0.00031236424 | V10: 0.0018398518 | W10: 0.0018381332 | X10: 0.0015216215 | Y10: 4.0002197e-05 | Z10: 0.00034003902 | AA10: -0.0005585513 | AB10: -1.0816353e-05 | AC10: -6.5378674e-06 | AD10: 0.00014281692 | AE10: 0.00024854446 | AF10: 0.00010586717 | AG10: -0.00018489091 | AH10: 0.00015831116 | AI10: -1.9249824e-05 | AJ10: 0.00016438064 | AK10: 4.499481e-05 | AL10: 4.9746751e-05 | AM10: 0.0003698939 | AN10: 4.7794464e-05 | AO10: 4.4923202e-06 | AP10: 4.1442547e-05 | AQ10: -0.00033432623 | AR10: 0.00023317862 | AS10: 5.4989084e-05 | AT10: 0.0010205094 | AU10: -0.002500441
A11: Ydses_c5_Q5_L1 | B11: 0.10641117 | C11: 0.00042040336 | D11: -0.00013777469 | E11: 3.3397641e-05 | F11: -5.0161281e-07 | G11: 4.3011823e-05 | H11: 0.00019159426 | I11: 0.0019657042 | J11: 0.0024810878 | K11: 0.0025261357 | L11: 0.0033298479 | M11: -3.3501921e-05 | N11: 4.9098549e-05 | O11: -0.00023075102 | P11: -0.001826835 | Q11: -0.0023617847 | R11: -0.002337727 | S11: -0.0032529925 | T11: -0.0005471102 | U11: -0.00035757788 | V11: 0.0016361762 | W11: 0.0015985581 | X11: 0.0012717783 | Y11: 4.6915518e-05 | Z11: 0.0004074467 | AA11: -0.00035117091 | AB11: -1.0829604e-05 | AC11: -1.102868e-05 | AD11: 0.00024157419 | AE11: 0.00024738389 | AF11: 0.00010888629 | AG11: -0.00010630017 | AH11: 0.00021492185 | AI11: 0.00012798796 | AJ11: 0.0003506034 | AK11: 7.3536829e-05 | AL11: 0.00015611419 | AM11: 0.00054836736 | AN11: 0.00014860515 | AO11: 1.8660615e-05 | AP11: -5.418261e-05 | AQ11: -0.00016605499 | AR11: -3.5251e-05 | AS11: 0.00026616509 | AT11: 0.00056098821 | AU11: -0.0020145094
A12: Ded_Dgn | B12: 0.25119503 | C12: -0.0061359492 | D12: -1.8559357e-05 | E12: 3.4310766e-05 | F12: -4.1108093e-07 | G12: -1.6492524e-05 | H12: 2.6692387e-05 | I12: 0.00013754961 | J12: 1.7495161e-05 | K12: 1.0763959e-05 | L12: -3.3501921e-05 | M12: 0.0342754 | N12: -0.0045503277 | O12: 0.0014533602 | P12: -0.0046639702 | Q12: -0.0086221649 | R12: -0.0023229742 | S12: -0.021998929 | T12: -0.00034021848 | U12: -0.00013113741 | V12: 0.0032347817 | W12: 7.8524529e-05 | X12: 0.00027405419 | Y12: -0.0078136253 | Z12: 3.3694988e-05 | AA12: -8.3145672e-06 | AB12: 1.6095071e-05 | AC12: 6.8500218e-06 | AD12: -0.00042605391 | AE12: -0.00018885298 | AF12: -0.00028234165 | AG12: -0.00032560755 | AH12: -0.00027135116 | AI12: -0.00022440794 | AJ12: 0.00063708579 | AK12: 8.3934845e-05 | AL12: -0.00019955207 | AM12: -0.00015661984 | AN12: -0.0002463879 | AO12: 7.9412135e-05 | AP12: -0.00029505442 | AQ12: -0.00033147527 | AR12: -8.148079e-05 | AS12: -0.0010183276 | AT12: 0.00021841843 | AU12: -0.0028803063
A13: Ded_Dnc_L1_ | B13: -0.11591726 | C13: -0.0056156104 | D13: -0.00010111487 | E13: -7.6821371e-06 | F13: 5.4952139e-08 | G13: -0.00031030463 | H13: 0.00052242506 | I13: 6.1381435e-05 | J13: 7.8562495e-05 | K13: 2.0442678e-05 | L13: 4.9098549e-05 | M13: -0.0045503277 | N13: 0.008137897 | O13: 0.0050132547 | P13: 0.0038632792 | Q13: 0.00012953859 | R13: 0.0052189202 | S13: 0.00074558005 | T13: -7.5698542e-06 | U13: -3.7312479e-05 | V13: -5.5958279e-05 | W13: -2.7797656e-05 | X13: -0.00012362725 | Y13: 0.00010190887 | Z13: 4.747249e-05 | AA13: 9.1795649e-05 | AB13: -4.8043636e-06 | AC13: -3.0651449e-06 | AD13: -3.5797041e-05 | AE13: -1.328079e-06 | AF13: 0.00010296711 | AG13: 8.9337068e-05 | AH13: -9.347592e-06 | AI13: 1.1349984e-05 | AJ13: -0.00021584953 | AK13: -0.00013966367 | AL13: 6.512563e-05 | AM13: 0.00012942881 | AN13: 6.9087224e-05 | AO13: -2.7513037e-05 | AP13: 0.00016687869 | AQ13: 0.00010887101 | AR13: -4.2844038e-05 | AS13: -7.261858e-05 | AT13: 0.00018985131 | AU13: 0.0011918482
... A46: Constant | B46: -2.2283075 | C46: -0.0041629364 | D46: -0.0009737044 | E46: -0.00071802051 | F46: 8.2210759e-06 | G46: -3.8924888e-05 | H46: -0.00013024887 | I46: -0.0026203578 | J46: -0.0030383983 | K46: -0.002500441 | L46: -0.0020145094 | M46: -0.0028803063 | N46: 0.0011918482 | O46: -0.0010528767 | P46: 0.0052665188 | Q46: 0.0048635032 | R46: 0.0050669324 | S46: 0.0020775045 | T46: -0.0010410233 | U46: -0.001082922 | V46: -0.0042801223 | W46: -0.0051435488 | X46: -0.006636889 | Y46: 0.00087230271 | Z46: 0.0021697284 | AA46: 0.0028259962 | AB46: -0.00013591247 | AC46: -8.0889204e-05 | AD46: 1.2562508e-05 | AE46: -0.0018358219 | AF46: -0.0016965311 | AG46: -0.0015315187 | AH46: -0.0021045932 | AI46: -0.0012256858 | AJ46: -0.0016257749 | AK46: -0.0019225664 | AL46: -0.0028527815 | AM46: -0.0026981225 | AN46: -0.0019891045 | AO46: -0.00030116265 | AP46: 0.00029355395 | AQ46: 0.0015973481 | AR46: 1.0466557e-05 | AS46: -0.00046843998 | AT46: -0.0015170272 | AU46: 0.035805266

Sheet U2_orig
A1: REGRESSOR | B1: COEFFICIENT | C1: Ded | D1: Dag | E1: Dag_sq | F1: Deh_c4_Na_L1 | G1: Deh_c4_Low_L1 | H1: Deh_c4_Medium_L1 | I1: Dehsp_c3_Medium_L1 | J1: Dehsp_c3_Low_L1 | K1: Dhe_Fair_L1 | L1: Dhe_Good_L1 | M1: Dhe_VeryGood_L1 | N1: Dhe_Excellent_L1 | O1: Dhe_pcs_L1 | P1: Dhe_mcs_L1 | Q1: Dhe_pcssp_L1 | R1: Dhe_mcssp_L1 | S1: Dcpyy_L1 | T1: New_rel_L1 | U1: Dcpagdf_L1 | V1: Dnc_L1 | W1: Dnc02_L1 | X1: Lesdf_c4_EmpSpouseNotEmp_L1 | Y1: Lesdf_c4_NotEmpSpouseEmp_L1 | Z1: Lesdf_c4_BothNotEmployed_L1 | AA1: Ypnbihs_dv_L1 | AB1: Ynbcpdf_dv_L1 | AC1: demRgnUKC | AD1: demRgnUKD | AE1: demRgnUKE | AF1: demRgnUKF | AG1: demRgnUKG | AH1: demRgnUKH | AI1: demRgnUKJ | AJ1: demRgnUKK | AK1: demRgnUKL | AL1: demRgnUKM | AM1: demRgnUKN | AN1: Year_transformed | AO1: Y2020 | AP1: Y2021 | AQ1: demEthnC4Asian | AR1: demEthnC4Black | AS1: demEthnC4Other | AT1: Constant
A2: Ded | B2: -0.18822354 | C2: 0.19636783 | D2: -3.3679953e-06 | E2: 1.8193184e-07 | F2: -0.10010041 | G2: -4.5825734e-05 | H2: -2.8284519e-05 | I2: 1.387984e-05 | J2: 2.9652325e-05 | K2: -0.00059286479 | L2: -0.00070526099 | M2: -0.00014204087 | N2: -0.00040179766 | O2: -1.5598824e-05 | P2: -9.807862e-06 | Q2: 1.6912144e-05 | R2: -1.930594e-05 | S2: 2.0553728e-08 | T2: 0.0002172103 | U2: -1.7263368e-05 | V2: -9.5912379e-05 | W2: -0.00017416261 | X2: 0.00076570305 | Y2: -0.0004128251 | Z2: -0.00071269939 | AA2: 1.6137623e-05 | AB2: -0.00011114268 | AC2: -0.00045339096 | AD2: -0.00070634258 | AE2: -0.00029094549 | AF2: -6.2908498e-05 | AG2: -0.0011271382 | AH2: -0.00030071883 | AI2: -0.000521018 | AJ2: -5.5431624e-05 | AK2: -0.0007295002 | AL2: -0.00039135993 | AM2: -0.00036348937 | AN2: -5.5376545e-05 | AO2: 0.0005260025 | AP2: 0.00039719694 | AQ2: 0.00088026827 | AR2: 0.00051478441 | AS2: 0.00013465572 | AT2: 0.0026721108
A3: Dag | B3: -0.047256376 | C3: -3.3679953e-06 | D3: 4.3086861e-05 | E3: -4.2451582e-07 | F3: 0.00017786664 | G3: 4.128533e-05 | H3: 1.3773399e-05 | I3: 1.1683099e-05 | J3: -7.7545908e-06 | K3: -7.4104129e-06 | L3: 7.841343e-06 | M3: 3.248267e-05 | N3: 1.2796493e-05 | O3: -1.0915981e-06 | P3: -5.9302672e-07 | Q3: 1.4671273e-06 | R3: 7.5706855e-07 | S3: -2.5482528e-06 | T3: 0.00010070224 | U3: 2.8993773e-07 | V3: -1.7470171e-05 | W3: 5.1256211e-05 | X3: 4.2012742e-05 | Y3: 1.2585098e-05 | Z3: 0.00010916709 | AA3: 2.3084976e-06 | AB3: -5.1511319e-06 | AC3: -1.7137351e-05 | AD3: 1.1420217e-05 | AE3: 1.9014901e-05 | AF3: -1.1558012e-05 | AG3: -5.0267209e-07 | AH3: 1.0539515e-05 | AI3: 1.2724695e-05 | AJ3: 1.9503535e-05 | AK3: -3.8610713e-06 | AL3: 1.4561661e-05 | AM3: -3.7198797e-05 | AN3: 4.0407591e-06 | AO3: -1.4821536e-05 | AP3: -3.5768489e-05 | AQ3: 4.5848895e-05 | AR3: -7.9334945e-06 | AS3: -9.6782408e-06 | AT3: -0.0011337566
A4: Dag_sq | B4: 0.00038201415 | C4: 1.8193184e-07 | D4: -4.2451582e-07 | E4: 4.4634273e-09 | F4: -1.2521037e-06 | G4: -4.2901867e-07 | H4: -1.3403889e-07 | I4: -1.4809696e-07 | J4: -8.5580014e-08 | K4: 1.5851457e-07 | L4: 7.7646234e-08 | M4: -1.0699582e-07 | N4: 9.9150929e-08 | O4: 1.0564701e-08 | P4: 1.3154553e-09 | Q4: -1.0286255e-08 | R4: -1.1867282e-08 | S4: 1.9041307e-08 | T4: -7.9498973e-07 | U4: -1.9145891e-08 | V4: 2.3467607e-07 | W4: -4.4877269e-07 | X4: -7.6375259e-07 | Y4: -4.3819564e-07 | Z4: -1.9009983e-06 | AA4: -9.0018684e-08 | AB4: 9.097626e-08 | AC4: 2.2290034e-07 | AD4: -4.3481962e-08 | AE4: -2.599588e-07 | AF4: 1.3339072e-07 | AG4: -7.731913e-08 | AH4: -6.6420037e-08 | AI4: -1.1931073e-07 | AJ4: -1.8527641e-07 | AK4: 5.264126e-09 | AL4: -2.0755774e-07 | AM4: 3.1811792e-07 | AN4: -4.4164205e-08 | AO4: 1.2343716e-07 | AP4: 3.5604499e-07 | AQ4: -4.4796351e-07 | AR4: -8.5811927e-08 | AS4: 9.0468984e-08 | AT4: 1.1342003e-05
A5: Deh_c4_Na_L1 | B5: -0.30605667 | C5: -0.10010041 | D5: 0.00017786664 | E5: -1.2521037e-06 | F5: 0.10422483 | G5: 0.0015114043 | H5: 0.00094837374 | I5: -0.00033176576 | J5: -0.00071788542 | K5: 0.00065476705 | L5: 0.00085726619 | M5: 0.00087478731 | N5: 0.00080280584 | O5: -9.3526241e-06 | P5: -2.3327251e-07 | Q5: -2.6625976e-07 | R5: 1.1426673e-06 | S5: -1.7090848e-05 | T5: -0.00057919005 | U5: -1.8776372e-05 | V5: 0.00024798878 | W5: 0.00051098268 | X5: -0.00016964647 | Y5: -0.0012655487 | Z5: -0.0015178845 | AA5: -2.0105179e-05 | AB5: -3.7058568e-06 | AC5: 0.00026916644 | AD5: 0.00055478879 | AE5: -9.0258816e-05 | AF5: 0.00012132822 | AG5: 0.0001507628 | AH5: 0.00067065892 | AI5: 0.00042791489 | AJ5: 3.1037341e-05 | AK5: 0.00054756624 | AL5: -6.3403992e-07 | AM5: 0.00029759562 | AN5: 1.7075576e-05 | AO5: -0.00022673969 | AP5: -0.00025545485 | AQ5: -0.00017187475 | AR5: -0.0007778984 | AS5: -0.00019761709 | AT5: -0.0061422105
A6: Deh_c4_Low_L1 | B6: 0.064428268 | C6: -4.5825734e-05 | D6: 4.128533e-05 | E6: -4.2901867e-07 | F6: 0.0015114043 | G6: 0.0036660541 | H6: 0.0012014725 | I6: -0.00062006023 | J6: -0.0011724919 | K6: 9.2419451e-05 | L6: 0.00049967212 | M6: 0.00047477866 | N6: 0.00048193526 | O6: -2.0767689e-06 | P6: -3.7722708e-06 | Q6: -6.3418991e-06 | R6: -3.1102151e-06 | S6: -1.0448347e-05 | T6: 0.00075749165 | U6: -4.7804132e-06 | V6: 0.00010779726 | W6: 2.0804244e-05 | X6: -0.00035414559 | Y6: 5.3692307e-05 | Z6: -0.00060057793 | AA6: 6.1011174e-05 | AB6: 3.7360974e-05 | AC6: -7.5486766e-05 | AD6: 0.00031781034 | AE6: -0.00037500188 | AF6: -3.6121032e-05 | AG6: -0.00037857593 | AH6: -0.00012125952 | AI6: -0.00010425993 | AJ6: -0.00011883966 | AK6: -0.00021412119 | AL6: 7.8842169e-05 | AM6: -0.00034175915 | AN6: 3.3373256e-05 | AO6: 0.00036086134 | AP6: -0.0002866947 | AQ6: 0.00014513106 | AR6: -0.00056056845 | AS6: -0.00039891611 | AT6: -0.0018441218
A7: Deh_c4_Medium_L1 | B7: 0.0765794 | C7: -2.8284519e-05 | D7: 1.3773399e-05 | E7: -1.3403889e-07 | F7: 0.00094837374 | G7: 0.0012014725 | H7: 0.0013012137 | I7: -0.00051188814 | J7: -0.00055294274 | K7: -0.00013800127 | L7: 0.00011991791 | M7: 0.00018475636 | N7: 0.0002155539 | O7: -2.5349727e-06 | P7: -3.155073e-06 | Q7: 4.547761e-06 | R7: -1.1412128e-06 | S7: -3.603704e-06 | T7: 0.00018347511 | U7: -5.6162307e-06 | V7: -4.8919309e-05 | W7: 0.00013703912 | X7: -3.5139839e-06 | Y7: 2.0487142e-05 | Z7: -9.70356e-05 | AA7: 7.9410179e-08 | AB7: 2.0534863e-05 | AC7: -1.7438004e-05 | AD7: 2.6826561e-05 | AE7: -0.00011850257 | AF7: -7.0458742e-06 | AG7: -0.0001191943 | AH7: 8.8260818e-05 | AI7: -2.2620753e-06 | AJ7: -0.000123337 | AK7: -5.1447104e-05 | AL7: -8.56814e-05 | AM7: 4.0038691e-05 | AN7: 2.210399e-05 | AO7: 1.8525528e-05 | AP7: -0.00019569874 | AQ7: 5.9832514e-05 | AR7: -0.00021048494 | AS7: -0.0004634071 | AT7: -0.0010838173
A8: Dehsp_c3_Medium_L1 | B8: 0.24482281 | C8: 1.387984e-05 | D8: 1.1683099e-05 | E8: -1.4809696e-07 | F8: -0.00033176576 | G8: -0.00062006023 | H8: -0.00051188814 | I8: 0.001456377 | J8: 0.0012303736 | K8: -0.00013997486 | L8: -0.00016629848 | M8: -0.00026687624 | N8: -0.0001249131 | O8: 1.5536715e-06 | P8: 1.2540284e-06 | Q8: 3.2029037e-06 | R8: -1.0042962e-07 | S8: -6.296635e-07 | T8: -0.00038881877 | U8: 1.6643853e-05 | V8: -1.363268e-06 | W8: 1.6818876e-05 | X8: 0.00046079241 | Y8: 3.9939104e-05 | Z8: 0.00034273537 | AA8: 7.1073314e-05 | AB8: -7.0975804e-05 | AC8: -0.00030372124 | AD8: -0.00027462765 | AE8: -0.00020315364 | AF8: -0.00038289816 | AG8: -0.00027185085 | AH8: -0.00053807095 | AI8: -0.00038290804 | AJ8: -0.00039488527 | AK8: -0.00033229925 | AL8: -0.00048501057 | AM8: -0.00029984899 | AN8: 2.4413412e-05 | AO8: -2.5707949e-05 | AP8: -0.00021329505 | AQ8: -7.0581294e-05 | AR8: 0.00017785638 | AS8: 0.0005122952 | AT8: -0.0015638058
A9: Dehsp_c3_Low_L1 | B9: 0.27635231 | C9: 2.9652325e-05 | D9: -7.7545908e-06 | E9: -8.5580014e-08 | F9: -0.00071788542 | G9: -0.0011724919 | H9: -0.00055294274 | I9: 0.0012303736 | J9: 0.0027855585 | K9: 6.9393741e-06 | L9: 1.453802e-05 | M9: -0.00023721741 | N9: -2.4667055e-05 | O9: 8.2203908e-06 | P9: -2.2418609e-07 | Q9: 1.8216471e-05 | R9: 4.6597835e-06 | S9: -1.0832661e-06 | T9: -0.00063810593 | U9: 2.396796e-05 | V9: 5.0435699e-05 | W9: 0.00013313099 | X9: 0.00050712137 | Y9: 7.2659698e-05 | Z9: 0.00086970303 | AA9: 8.1056634e-05 | AB9: -7.204697e-05 | AC9: -0.00034026931 | AD9: -0.00043898863 | AE9: -0.00032711844 | AF9: -0.00041261926 | AG9: 5.0523352e-05 | AH9: -0.00056548351 | AI9: -0.00036046501 | AJ9: -0.0002543728 | AK9: -0.00035708108 | AL9: -0.00051819173 | AM9: -0.00015829615 | AN9: 4.1127229e-05 | AO9: -3.0778736e-05 | AP9: -0.00018605144 | AQ9: -0.00034025695 | AR9: 0.00055056546 | AS9: 0.0002705857 | AT9: -0.0027156125
A10: Dhe_Fair_L1 | B10: 0.1449211 | C10: -0.00059286479 | D10: -7.4104129e-06 | E10: 1.5851457e-07 | F10: 0.00065476705 | G10: 9.2419451e-05 | H10: -0.00013800127 | I10: -0.00013997486 | J10: 6.9393741e-06 | K10: 0.0071249716 | L10: 0.0068295009 | M10: 0.0072960977 | N10: 0.0074564592 | O10: -6.7243795e-05 | P10: -3.2632186e-05 | Q10: 1.3892916e-05 | R10: -4.6773048e-06 | S10: -9.3831153e-07 | T10: -6.4642853e-06 | U10: -3.1017841e-05 | V10: 0.00014069263 | W10: -0.00015708193 | X10: -0.00086157033 | Y10: -0.00022646348 | Z10: -0.00018621767 | AA10: -8.0112223e-05 | AB10: 0.0001064997 | AC10: -0.00011906334 | AD10: 0.00021481512 | AE10: -0.0010427582 | AF10: -2.9302892e-05 | AG10: 2.0618337e-05 | AH10: 5.9196101e-05 | AI10: -0.0001320559 | AJ10: 0.0002596841 | AK10: -5.0021881e-05 | AL10: 7.2887756e-05 | AM10: -0.00033948698 | AN10: -4.3108475e-05 | AO10: 0.000187255 | AP10: 0.00050303619 | AQ10: 1.6027e-05 | AR10: -7.0042998e-06 | AS10: 0.00018800305 | AT10: -0.00096502767
A11: Dhe_Good_L1 | B11: 0.17396464 | C11: -0.00070526099 | D11: 7.841343e-06 | E11: 7.7646234e-08 | F11: 0.00085726619 | G11: 0.00049967212 | H11: 0.00011991791 | I11: -0.00016629848 | J11: 1.453802e-05 | K11: 0.0068295009 | L11: 0.0093951244 | M11: 0.0096635259 | N11: 0.010030196 | O11: -0.00012693845 | P11: -6.27967e-05 | Q11: 1.5156875e-05 | R11: -9.3916964e-06 | S11: -8.278835e-06 | T11: 5.6394062e-05 | U11: -3.0315407e-05 | V11: 9.5776649e-05 | W11: -0.0001135103 | X11: -0.0013326562 | Y11: -0.00027197014 | Z11: -0.00071087773 | AA11: -0.00014757317 | AB11: 0.00014893879 | AC11: -0.00051137332 | AD11: 0.00022142328 | AE11: -0.0013199667 | AF11: -0.00044525265 | AG11: -0.00032865594 | AH11: -0.0002955736 | AI11: -0.0005655217 | AJ11: -3.2872486e-05 | AK11: -0.00047779185 | AL11: -0.00024230542 | AM11: -0.00075094329 | AN11: 2.9949361e-06 | AO11: 0.00030506509 | AP11: 0.00024588975 | AQ11: -0.00030432229 | AR11: -0.00011949274 | AS11: -0.00041838182 | AT11: 0.0012421896
A12: Dhe_VeryGood_L1 | B12: 0.21576151 | C12: -0.00014204087 | D12: 3.248267e-05 | E12: -1.0699582e-07 | F12: 0.00087478731 | G12: 0.00047477866 | H12: 0.00018475636 | I12: -0.00026687624 | J12: -0.00023721741 | K12: 0.0072960977 | L12: 0.0096635259 | M12: 0.011396534 | N12: 0.011359105 | O12: -0.0001639085 | P12: -7.9496199e-05 | Q12: 1.8727834e-05 | R12: -1.5511763e-05 | S12: -1.0534891e-05 | T12: 1.9071671e-05 | U12: -4.0050028e-05 | V12: 1.5585721e-05 | W12: -0.0001310151 | X12: -0.001025976 | Y12: -0.00034289905 | Z12: -0.0008880552 | AA12: -0.00014559527 | AB12: 0.00013139279 | AC12: -0.00031663639 | AD12: 0.00012347502 | AE12: -0.001129942 | AF12: -0.00028004489 | AG12: -0.00051725738 | AH12: -6.3288648e-05 | AI12: -0.00043254359 | AJ12: 2.8221821e-05 | AK12: -0.00029745123 | AL12: -9.5650526e-05 | AM12: -0.00064082365 | AN12: -5.3020809e-06 | AO12: 0.00019081023 | AP12: 0.00039613545 | AQ12: -0.00012829284 | AR12: -0.00012016096 | AS12: -0.00061807204 | AT12: 0.0025299769
A13: Dhe_Excellent_L1 | B13: 0.2527093 | C13: -0.00040179766 | D13: 1.2796493e-05 | E13: 9.9150929e-08 | F13: 0.00080280584 | G13: 0.00048193526 | H13: 0.0002155539 | I13: -0.0001249131 | J13: -2.4667055e-05 | K13: 0.0074564592 | L13: 0.010030196 | M13: 0.011359105 | N13: 0.013283907 | O13: -0.0001733317 | P13: -8.7279638e-05 | Q13: 1.9181392e-05 | R13: -1.2880901e-05 | S13: -1.2541017e-05 | T13: -7.5465635e-05 | U13: -4.5369596e-05 | V13: 2.4177582e-05 | W13: -0.00022994552 | X13: -0.0012211204 | Y13: -0.00019162038 | Z13: -0.0010353858 | AA13: -0.00015787287 | AB13: 0.00013715089 | AC13: -0.00044225821 | AD13: 5.8327373e-05 | AE13: -0.0010240597 | AF13: -0.00043931485 | AG13: -0.00068261179 | AH13: -0.00025490574 | AI13: -0.00059435228 | AJ13: -0.00011039277 | AK13: -0.0005119023 | AL13: -0.00039966928 | AM13: -0.00044859949 | AN13: 2.3310868e-05 | AO13: 6.2784335e-05 | AP13: 0.00011498531 | AQ13: -0.0002724292 | AR13: -0.00014425678 | AS13: -0.00066666504 | AT13: 0.0029365658
... A45: Constant | B45: 0.36336029 | C45: 0.0026721108 | D45: -0.0011337566 | E45: 1.1342003e-05 | F45: -0.0061422105 | G45: -0.0018441218 | H45: -0.0010838173 | I45: -0.0015638058 | J45: -0.0027156125 | K45: -0.00096502767 | L45: 0.0012421896 | M45: 0.0025299769 | N45: 0.0029365658 | O45: -0.00016886352 | P45: -8.5029573e-05 | Q45: -0.00019773948 | R45: -0.00010662566 | S45: 9.1458354e-05 | T45: -0.0032505096 | U45: -1.2505217e-05 | V45: -0.00029454762 | W45: -0.0017686285 | X45: -0.0063695055 | Y45: -0.0023324689 | Z45: -0.0092774636 | AA45: -0.00062267952 | AB45: 0.00045593596 | AC45: -0.0036064579 | AD45: -0.0051674845 | AE45: -0.0037489982 | AF45: -0.0037220177 | AG45: -0.005771101 | AH45: -0.0032371313 | AI45: -0.0044290797 | AJ45: -0.0039958352 | AK45: -0.003955478 | AL45: -0.0040681466 | AM45: -0.0033976571 | AN45: -0.00051153927 | AO45: 0.0013896911 | AP45: 0.0024543385 | AQ45: -0.0024167619 | AR45: -0.00065399036 | AS45: -0.0015016752 | AT45: 0.072668695

Sheet U1
A1: REGRESSOR | B1: COEFFICIENT | C1: eduSampleFlag | D1: demMaleFlag | E1: demAge | F1: demAgeSq | G1: demNChildL1 | H1: demNChild0to2L1 | I1: yHhQuintilesMonthC5Q2L1 | J1: yHhQuintilesMonthC5Q3L1 | K1: yHhQuintilesMonthC5Q4L1 | L1: yHhQuintilesMonthC5Q5L1 | M1: eduSampleFlag_demMaleFlag | N1: eduSampleFlag_demNChildL1 | O1: eduSampleFlag_demNChild0to2L1 | P1: eduSampleFlag_Q2L1 | Q1: eduSampleFlag_Q3L1 | R1: eduSampleFlag_Q4L1 | S1: eduSampleFlag_Q5L1 | T1: eduHighestC4High | U1: eduHighestC4Medium | V1: labStatusC4StudentL1 | W1: labStatusC4NotEmployedL1 | X1: labStatusC4RetiredL1 | Y1: labStatusC4Student_MaleL1 | Z1: labStatusC4NotEmployed_MaleL1 | AA1: labStatusC4Retired_MaleL1 | AB1: healthPhysicalPcsL1 | AC1: healthMentalMcsL1 | AD1: demRgnUKC | AE1: demRgnUKD | AF1: demRgnUKE | AG1: demRgnUKF | AH1: demRgnUKG | AI1: demRgnUKH | AJ1: demRgnUKJ | AK1: demRgnUKK | AL1: demRgnUKL | AM1: demRgnUKM | AN1: demRgnUKN | AO1: demYearTransformed | AP1: demYear2020 | AQ1: demYear2021 | AR1: demEthnC4Asian | AS1: demEthnC4Black | AT1: demEthnC4Other | AU1: Constant
A2: eduSampleFlag | B2: -0.32653155 | C2: 0.022120545 | D2: 0.00031805057 | E2: 9.0673993e-05 | F2: -1.0070022e-06 | G2: 0.00018046448 | H2: -2.8366006e-05 | I2: 0.00061920924 | J2: 0.00028422119 | K2: 0.00059041247 | L2: 0.00042040336 | M2: -0.0061359492 | N2: -0.0056156104 | O2: -0.0018677534 | P2: -0.015137141 | Q2: -0.0098032047 | R2: -0.015810559 | S2: -0.0051891541 | T2: 0.0019436598 | U2: 0.0019151458 | V2: -0.0023403046 | W2: 0.00099997364 | X2: 0.0013051876 | Y2: 0.0028725921 | Z2: -0.00022638964 | AA2: -0.00033171819 | AB2: -7.7079369e-06 | AC2: 7.2758599e-08 | AD2: -0.00014390658 | AE2: -2.8564721e-05 | AF2: -5.5780428e-05 | AG2: -0.00011398151 | AH2: 0.00015761292 | AI2: 2.5996757e-05 | AJ2: 0.00058236727 | AK2: -8.2699773e-05 | AL2: -0.00050106306 | AM2: -0.00013507363 | AN2: 0.00012565942 | AO2: 8.6155511e-06 | AP2: -7.0367987e-05 | AQ2: -3.2984526e-05 | AR2: -0.00019976217 | AS2: 0.00093400101 | AT2: -0.00029281012 | AU2: -0.0041629364
A3: demMaleFlag | B3: 0.022031232 | C3: 0.00031805057 | D3: 0.00091918944 | E3: 5.2566515e-06 | F3: -2.0498773e-08 | G3: 9.6728785e-05 | H3: -3.5872067e-05 | I3: 2.9119515e-05 | J3: -7.8166952e-05 | K3: -9.8187629e-05 | L3: -0.00013777469 | M3: -1.8559357e-05 | N3: -0.00010111487 | O3: 5.2385963e-05 | P3: -1.6986439e-05 | Q3: 8.324256e-05 | R3: 9.7554909e-05 | S3: 0.00012058235 | T3: 0.00039443283 | U3: 0.00020796098 | V3: 0.00040646992 | W3: 0.00042443365 | X3: 0.00038439503 | Y3: -0.00091032799 | Z3: -0.00086469719 | AA3: -0.00090664118 | AB3: 1.9802191e-06 | AC3: 2.6256133e-06 | AD3: -0.00012369198 | AE3: -3.7715059e-05 | AF3: -5.9915341e-05 | AG3: -5.9244339e-05 | AH3: -2.6828693e-05 | AI3: -0.00011245049 | AJ3: -0.00012869516 | AK3: -3.80687e-05 | AL3: -5.9252026e-06 | AM3: -0.00022940907 | AN3: -9.7870477e-05 | AO3: 1.4920262e-06 | AP3: 3.079314e-05 | AQ3: 5.7561717e-05 | AR3: -6.5745389e-05 | AS3: -7.4825504e-06 | AT3: -0.00020955188 | AU3: -0.0009737044
A4: demAge | B4: 0.031052981 | C4: 9.0673993e-05 | D4: 5.2566515e-06 | E4: 3.1938768e-05 | F4: -3.9865157e-07 | G4: -6.6460658e-06 | H4: 1.2431699e-05 | I4: 4.0973435e-05 | J4: 4.2632714e-05 | K4: 4.966429e-05 | L4: 3.3397641e-05 | M4: 3.4310766e-05 | N4: -7.6821371e-06 | O4: 1.2715653e-05 | P4: -9.916009e-05 | Q4: -6.8564221e-05 | R4: -7.0986113e-05 | S4: -5.66922e-05 | T4: 1.4085399e-05 | U4: 3.4165599e-05 | V4: 0.00010917283 | W4: 7.1829224e-05 | X4: 0.00030958339 | Y4: 1.1829265e-05 | Z4: -5.8527936e-06 | AA4: -8.0067008e-05 | AB4: 6.2778453e-07 | AC4: 6.6394116e-08 | AD4: -4.0932221e-05 | AE4: 8.1417109e-06 | AF4: 1.083561e-05 | AG4: 5.4424427e-06 | AH4: 1.8764822e-05 | AI4: -1.4786838e-05 | AJ4: 2.2945529e-05 | AK4: 1.7827662e-05 | AL4: -2.3727468e-05 | AM4: 3.3322105e-05 | AN4: 2.4128471e-05 | AO4: 1.7337031e-06 | AP4: -4.5125372e-06 | AQ4: -2.6286666e-05 | AR4: -3.3731695e-06 | AS4: -2.2089806e-05 | AT4: 4.9469772e-05 | AU4: -0.00071802051
A5: demAgeSq | B5: -0.0005674011 | C5: -1.0070022e-06 | D5: -2.0498773e-08 | E5: -3.9865157e-07 | F5: 5.1676039e-09 | G5: 1.013915e-07 | H5: -1.1036609e-07 | I5: -4.7591378e-07 | J5: -5.1324166e-07 | K5: -6.7104715e-07 | L5: -5.0161281e-07 | M5: -4.1108093e-07 | N5: 5.4952139e-08 | O5: -2.0246041e-07 | P5: 1.1480227e-06 | Q5: 8.1458452e-07 | R5: 8.8430769e-07 | S5: 7.4359265e-07 | T5: -1.2285366e-07 | U5: -3.3766934e-07 | V5: -1.1763224e-06 | W5: -8.5381969e-07 | X5: -4.4206417e-06 | Y5: -1.6980182e-07 | Z5: 8.8332328e-08 | AA5: 1.0294289e-06 | AB5: -1.7343914e-09 | AC5: 4.9532923e-10 | AD5: 4.0315398e-07 | AE5: -1.4511933e-07 | AF5: -1.3338915e-07 | AG5: -8.2971252e-08 | AH5: -2.0507833e-07 | AI5: 2.1943885e-07 | AJ5: -2.9718368e-07 | AK5: -2.0237247e-07 | AL5: 4.7119598e-07 | AM5: -4.8539976e-07 | AN5: -2.7137905e-07 | AO5: -2.2496086e-08 | AP5: 1.0355352e-07 | AQ5: 2.6619799e-07 | AR5: 1.1846346e-07 | AS5: 2.0514295e-07 | AT5: -7.0303385e-07 | AU5: 8.2210759e-06
A6: demNChildL1 | B6: -0.00057938553 | C6: 0.00018046448 | D6: 9.6728785e-05 | E6: -6.6460658e-06 | F6: 1.013915e-07 | G6: 0.00031831358 | H6: -0.00053739877 | I6: -5.232067e-05 | J6: -6.1433537e-05 | K6: 1.8367624e-05 | L6: 4.3011823e-05 | M6: -1.6492524e-05 | N6: -0.00031030463 | O6: 0.00053609105 | P6: 7.2557258e-05 | Q6: 6.4512225e-05 | R6: -1.0180196e-05 | S6: -3.9197131e-05 | T6: 7.0594962e-05 | U6: 5.8648136e-05 | V6: 6.6987425e-06 | W6: 1.6031272e-05 | X6: 5.5154432e-05 | Y6: -9.5460542e-05 | Z6: -6.1886474e-05 | AA6: -9.2447399e-05 | AB6: -5.4147812e-07 | AC6: 3.8389547e-08 | AD6: 6.7907952e-06 | AE6: 4.4614118e-05 | AF6: 3.269575e-05 | AG6: 5.032305e-05 | AH6: 3.305206e-06 | AI6: 2.1044895e-05 | AJ6: 1.5742576e-05 | AK6: 4.6893055e-05 | AL6: 1.6328994e-05 | AM6: -3.335231e-05 | AN6: -3.5791927e-05 | AO6: -2.9155323e-06 | AP6: -2.415156e-05 | AQ6: 6.3062338e-05 | AR6: -2.5981278e-05 | AS6: -5.6910292e-05 | AT6: -0.00014292045 | AU6: -3.8924888e-05
A7: demNChild0to2L1 | B7: 0.10180174 | C7: -2.8366006e-05 | D7: -3.5872067e-05 | E7: 1.2431699e-05 | F7: -1.1036609e-07 | G7: -0.00053739877 | H7: 0.0033599961 | I7: 0.00015915559 | J7: 0.00031050228 | K7: 0.00021122026 | L7: 0.00019159426 | M7: 2.6692387e-05 | N7: 0.00052242506 | O7: -0.0033597475 | P7: -0.0001766442 | Q7: -0.00033201247 | R7: -0.00022423216 | S7: -0.0002791401 | T7: 2.5605107e-05 | U7: -4.7946933e-05 | V7: 0.00026553607 | W7: -0.00025060276 | X7: -9.5085599e-05 | Y7: 6.8059694e-05 | Z7: 0.00060656481 | AA7: 3.8639042e-05 | AB7: -3.5421064e-06 | AC7: -2.0375662e-06 | AD7: 7.1089864e-05 | AE7: -1.1558806e-05 | AF7: 0.00017966872 | AG7: -0.00011724068 | AH7: 0.00027625644 | AI7: 0.00015776281 | AJ7: 5.0235387e-05 | AK7: 6.7752955e-05 | AL7: 0.00012421664 | AM7: 0.0001628578 | AN7: 2.7816442e-05 | AO7: -5.5839704e-06 | AP7: 0.00030078104 | AQ7: -2.7848104e-05 | AR7: 1.925751e-05 | AS7: -3.8229327e-05 | AT7: -2.0472481e-05 | AU7: -0.00013024887
A8: yHhQuintilesMonthC5Q2L1 | B8: -0.082073094 | C8: 0.00061920924 | D8: 2.9119515e-05 | E8: 4.0973435e-05 | F8: -4.7591378e-07 | G8: -5.232067e-05 | H8: 0.00015915559 | I8: 0.0025521847 | J8: 0.0021183025 | K8: 0.0020878058 | L8: 0.0019657042 | M8: 0.00013754961 | N8: 6.1381435e-05 | O8: -0.00013798332 | P8: -0.0025589498 | Q8: -0.0020963129 | R8: -0.0019914254 | S8: -0.001968976 | T8: -0.00012373296 | U8: -0.00017378026 | V8: 0.0015341079 | W8: 0.001478136 | X8: 0.00059190859 | Y8: -0.00017442095 | Z8: 0.00016339479 | AA8: -0.00024524295 | AB8: -4.5759165e-06 | AC8: -5.8470815e-07 | AD8: -5.3216888e-05 | AE8: 0.00016165516 | AF8: -5.8312048e-05 | AG8: -0.00031503401 | AH8: 7.2434037e-05 | AI8: -1.5067285e-05 | AJ8: 9.9211914e-05 | AK8: -9.7982037e-05 | AL8: -0.00019147226 | AM8: -5.9455414e-06 | AN8: 9.654825e-05 | AO8: 8.7115984e-06 | AP8: 0.00013163899 | AQ8: -0.00029121168 | AR8: 5.0245198e-05 | AS8: -1.6893054e-05 | AT8: 0.0002279893 | AU8: -0.0026203578
A9: yHhQuintilesMonthC5Q3L1 | B9: -0.035287234 | C9: 0.00028422119 | D9: -7.8166952e-05 | E9: 4.2632714e-05 | F9: -5.1324166e-07 | G9: -6.1433537e-05 | H9: 0.00031050228 | I9: 0.0021183025 | J9: 0.0032940066 | K9: 0.0026170018 | L9: 0.0024810878 | M9: 1.7495161e-05 | N9: 7.8562495e-05 | O9: -0.0002722754 | P9: -0.0021339881 | Q9: -0.0032789688 | R9: -0.0025032394 | S9: -0.0025034082 | T9: -0.00060037113 | U9: -0.0006637542 | V9: 0.0018994009 | W9: 0.0018959744 | X9: 0.00084964813 | Y9: 6.311371e-05 | Z9: 0.00024280861 | AA9: -0.00032576536 | AB9: -3.3645144e-06 | AC9: -2.350867e-06 | AD9: 0.00022979942 | AE9: 0.00035440835 | AF9: 4.3131043e-06 | AG9: -0.00021505991 | AH9: 0.00018763252 | AI9: 3.5850996e-05 | AJ9: 0.00013011618 | AK9: 4.8637504e-06 | AL9: 0.00012337431 | AM9: 0.00010738078 | AN9: 0.00015687387 | AO9: 2.5794233e-05 | AP9: 6.2036958e-05 | AQ9: -0.000375827 | AR9: 0.00010056824 | AS9: -2.9270166e-05 | AT9: 0.00033027949 | AU9: -0.0030383983
A10: yHhQuintilesMonthC5Q4L1 | B10: -0.012139572 | C10: 0.00059041247 | D10: -9.8187629e-05 | E10: 4.966429e-05 | F10: -6.7104715e-07 | G10: 1.8367624e-05 | H10: 0.00021122026 | I10: 0.0020878058 | J10: 0.0026170018 | K10: 0.003186341 | L10: 0.0025261357 | M10: 1.0763959e-05 | N10: 2.0442678e-05 | O10: -0.00024333002 | P10: -0.0020538256 | Q10: -0.0025455577 | R10: -0.0030140641 | S10: -0.0024939893 | T10: -0.00032152296 | U10: -0.00031236424 | V10: 0.0018398518 | W10: 0.0018381332 | X10: 0.0015216215 | Y10: 4.0002197e-05 | Z10: 0.00034003902 | AA10: -0.0005585513 | AB10: -1.0816353e-05 | AC10: -6.5378674e-06 | AD10: 0.00014281692 | AE10: 0.00024854446 | AF10: 0.00010586717 | AG10: -0.00018489091 | AH10: 0.00015831116 | AI10: -1.9249824e-05 | AJ10: 0.00016438064 | AK10: 4.499481e-05 | AL10: 4.9746751e-05 | AM10: 0.0003698939 | AN10: 4.7794464e-05 | AO10: 4.4923202e-06 | AP10: 4.1442547e-05 | AQ10: -0.00033432623 | AR10: 0.00023317862 | AS10: 5.4989084e-05 | AT10: 0.0010205094 | AU10: -0.002500441
A11: yHhQuintilesMonthC5Q5L1 | B11: 0.10641117 | C11: 0.00042040336 | D11: -0.00013777469 | E11: 3.3397641e-05 | F11: -5.0161281e-07 | G11: 4.3011823e-05 | H11: 0.00019159426 | I11: 0.0019657042 | J11: 0.0024810878 | K11: 0.0025261357 | L11: 0.0033298479 | M11: -3.3501921e-05 | N11: 4.9098549e-05 | O11: -0.00023075102 | P11: -0.001826835 | Q11: -0.0023617847 | R11: -0.002337727 | S11: -0.0032529925 | T11: -0.0005471102 | U11: -0.00035757788 | V11: 0.0016361762 | W11: 0.0015985581 | X11: 0.0012717783 | Y11: 4.6915518e-05 | Z11: 0.0004074467 | AA11: -0.00035117091 | AB11: -1.0829604e-05 | AC11: -1.102868e-05 | AD11: 0.00024157419 | AE11: 0.00024738389 | AF11: 0.00010888629 | AG11: -0.00010630017 | AH11: 0.00021492185 | AI11: 0.00012798796 | AJ11: 0.0003506034 | AK11: 7.3536829e-05 | AL11: 0.00015611419 | AM11: 0.00054836736 | AN11: 0.00014860515 | AO11: 1.8660615e-05 | AP11: -5.418261e-05 | AQ11: -0.00016605499 | AR11: -3.5251e-05 | AS11: 0.00026616509 | AT11: 0.00056098821 | AU11: -0.0020145094
A12: eduSampleFlag_demMaleFlag | B12: 0.25119503 | C12: -0.0061359492 | D12: -1.8559357e-05 | E12: 3.4310766e-05 | F12: -4.1108093e-07 | G12: -1.6492524e-05 | H12: 2.6692387e-05 | I12: 0.00013754961 | J12: 1.7495161e-05 | K12: 1.0763959e-05 | L12: -3.3501921e-05 | M12: 0.0342754 | N12: -0.0045503277 | O12: 0.0014533602 | P12: -0.0046639702 | Q12: -0.0086221649 | R12: -0.0023229742 | S12: -0.021998929 | T12: -0.00034021848 | U12: -0.00013113741 | V12: 0.0032347817 | W12: 7.8524529e-05 | X12: 0.00027405419 | Y12: -0.0078136253 | Z12: 3.3694988e-05 | AA12: -8.3145672e-06 | AB12: 1.6095071e-05 | AC12: 6.8500218e-06 | AD12: -0.00042605391 | AE12: -0.00018885298 | AF12: -0.00028234165 | AG12: -0.00032560755 | AH12: -0.00027135116 | AI12: -0.00022440794 | AJ12: 0.00063708579 | AK12: 8.3934845e-05 | AL12: -0.00019955207 | AM12: -0.00015661984 | AN12: -0.0002463879 | AO12: 7.9412135e-05 | AP12: -0.00029505442 | AQ12: -0.00033147527 | AR12: -8.148079e-05 | AS12: -0.0010183276 | AT12: 0.00021841843 | AU12: -0.0028803063
A13: eduSampleFlag_demNChildL1 | B13: -0.11591726 | C13: -0.0056156104 | D13: -0.00010111487 | E13: -7.6821371e-06 | F13: 5.4952139e-08 | G13: -0.00031030463 | H13: 0.00052242506 | I13: 6.1381435e-05 | J13: 7.8562495e-05 | K13: 2.0442678e-05 | L13: 4.9098549e-05 | M13: -0.0045503277 | N13: 0.008137897 | O13: 0.0050132547 | P13: 0.0038632792 | Q13: 0.00012953859 | R13: 0.0052189202 | S13: 0.00074558005 | T13: -7.5698542e-06 | U13: -3.7312479e-05 | V13: -5.5958279e-05 | W13: -2.7797656e-05 | X13: -0.00012362725 | Y13: 0.00010190887 | Z13: 4.747249e-05 | AA13: 9.1795649e-05 | AB13: -4.8043636e-06 | AC13: -3.0651449e-06 | AD13: -3.5797041e-05 | AE13: -1.328079e-06 | AF13: 0.00010296711 | AG13: 8.9337068e-05 | AH13: -9.347592e-06 | AI13: 1.1349984e-05 | AJ13: -0.00021584953 | AK13: -0.00013966367 | AL13: 6.512563e-05 | AM13: 0.00012942881 | AN13: 6.9087224e-05 | AO13: -2.7513037e-05 | AP13: 0.00016687869 | AQ13: 0.00010887101 | AR13: -4.2844038e-05 | AS13: -7.261858e-05 | AT13: 0.00018985131 | AU13: 0.0011918482
... A46: Constant | B46: -2.2283075 | C46: -0.0041629364 | D46: -0.0009737044 | E46: -0.00071802051 | F46: 8.2210759e-06 | G46: -3.8924888e-05 | H46: -0.00013024887 | I46: -0.0026203578 | J46: -0.0030383983 | K46: -0.002500441 | L46: -0.0020145094 | M46: -0.0028803063 | N46: 0.0011918482 | O46: -0.0010528767 | P46: 0.0052665188 | Q46: 0.0048635032 | R46: 0.0050669324 | S46: 0.0020775045 | T46: -0.0010410233 | U46: -0.001082922 | V46: -0.0042801223 | W46: -0.0051435488 | X46: -0.006636889 | Y46: 0.00087230271 | Z46: 0.0021697284 | AA46: 0.0028259962 | AB46: -0.00013591247 | AC46: -8.0889204e-05 | AD46: 1.2562508e-05 | AE46: -0.0018358219 | AF46: -0.0016965311 | AG46: -0.0015315187 | AH46: -0.0021045932 | AI46: -0.0012256858 | AJ46: -0.0016257749 | AK46: -0.0019225664 | AL46: -0.0028527815 | AM46: -0.0026981225 | AN46: -0.0019891045 | AO46: -0.00030116265 | AP46: 0.00029355395 | AQ46: 0.0015973481 | AR46: 1.0466557e-05 | AS46: -0.00046843998 | AT46: -0.0015170272 | AU46: 0.035805266

Sheet U2
A1: REGRESSOR | B1: COEFFICIENT | C1: eduSampleFlag | D1: demAge | E1: demAgeSq | F1: eduHighestC4NaL1 | G1: eduHighestC4LowL1 | H1: eduHighestC4MediumL1 | I1: eduHighestPartnerC3MediumL1 | J1: eduHighestPartnerC3LowL1 | K1: healthSelfRatedFairL1 | L1: healthSelfRatedGoodL1 | M1: healthSelfRatedVeryGoodL1 | N1: healthSelfRatedExcellentL1 | O1: healthPhysicalPcsL1 | P1: healthMentalMcsL1 | Q1: healthPhysicalPartnerPcsL1 | R1: healthMentalPartnerMcsL1 | S1: demPartnerNYearL1 | T1: demEnterPartnerFlagL1 | U1: demAgePartnerDiffL1 | V1: demNChildL1 | W1: demNChild0to2L1 | X1: labStatusPartnerAndOwnC42L1 | Y1: labStatusPartnerAndOwnC43L1 | Z1: labStatusPartnerAndOwnC44L1 | AA1: yNonBenPersGrossMonthL1 | AB1: yPersAndPartnerGrossDiffMonthL1 | AC1: demRgnUKC | AD1: demRgnUKD | AE1: demRgnUKE | AF1: demRgnUKF | AG1: demRgnUKG | AH1: demRgnUKH | AI1: demRgnUKJ | AJ1: demRgnUKK | AK1: demRgnUKL | AL1: demRgnUKM | AM1: demRgnUKN | AN1: demYearTransformed | AO1: demYear2020 | AP1: demYear2021 | AQ1: demEthnC4Asian | AR1: demEthnC4Black | AS1: demEthnC4Other | AT1: Constant
A2: eduSampleFlag | B2: -0.18822354 | C2: 0.19636783 | D2: -3.3679953e-06 | E2: 1.8193184e-07 | F2: -0.10010041 | G2: -4.5825734e-05 | H2: -2.8284519e-05 | I2: 1.387984e-05 | J2: 2.9652325e-05 | K2: -0.00059286479 | L2: -0.00070526099 | M2: -0.00014204087 | N2: -0.00040179766 | O2: -1.5598824e-05 | P2: -9.807862e-06 | Q2: 1.6912144e-05 | R2: -1.930594e-05 | S2: 2.0553728e-08 | T2: 0.0002172103 | U2: -1.7263368e-05 | V2: -9.5912379e-05 | W2: -0.00017416261 | X2: 0.00076570305 | Y2: -0.0004128251 | Z2: -0.00071269939 | AA2: 1.6137623e-05 | AB2: -0.00011114268 | AC2: -0.00045339096 | AD2: -0.00070634258 | AE2: -0.00029094549 | AF2: -6.2908498e-05 | AG2: -0.0011271382 | AH2: -0.00030071883 | AI2: -0.000521018 | AJ2: -5.5431624e-05 | AK2: -0.0007295002 | AL2: -0.00039135993 | AM2: -0.00036348937 | AN2: -5.5376545e-05 | AO2: 0.0005260025 | AP2: 0.00039719694 | AQ2: 0.00088026827 | AR2: 0.00051478441 | AS2: 0.00013465572 | AT2: 0.0026721108
A3: demAge | B3: -0.047256376 | C3: -3.3679953e-06 | D3: 4.3086861e-05 | E3: -4.2451582e-07 | F3: 0.00017786664 | G3: 4.128533e-05 | H3: 1.3773399e-05 | I3: 1.1683099e-05 | J3: -7.7545908e-06 | K3: -7.4104129e-06 | L3: 7.841343e-06 | M3: 3.248267e-05 | N3: 1.2796493e-05 | O3: -1.0915981e-06 | P3: -5.9302672e-07 | Q3: 1.4671273e-06 | R3: 7.5706855e-07 | S3: -2.5482528e-06 | T3: 0.00010070224 | U3: 2.8993773e-07 | V3: -1.7470171e-05 | W3: 5.1256211e-05 | X3: 4.2012742e-05 | Y3: 1.2585098e-05 | Z3: 0.00010916709 | AA3: 2.3084976e-06 | AB3: -5.1511319e-06 | AC3: -1.7137351e-05 | AD3: 1.1420217e-05 | AE3: 1.9014901e-05 | AF3: -1.1558012e-05 | AG3: -5.0267209e-07 | AH3: 1.0539515e-05 | AI3: 1.2724695e-05 | AJ3: 1.9503535e-05 | AK3: -3.8610713e-06 | AL3: 1.4561661e-05 | AM3: -3.7198797e-05 | AN3: 4.0407591e-06 | AO3: -1.4821536e-05 | AP3: -3.5768489e-05 | AQ3: 4.5848895e-05 | AR3: -7.9334945e-06 | AS3: -9.6782408e-06 | AT3: -0.0011337566
A4: demAgeSq | B4: 0.00038201415 | C4: 1.8193184e-07 | D4: -4.2451582e-07 | E4: 4.4634273e-09 | F4: -1.2521037e-06 | G4: -4.2901867e-07 | H4: -1.3403889e-07 | I4: -1.4809696e-07 | J4: -8.5580014e-08 | K4: 1.5851457e-07 | L4: 7.7646234e-08 | M4: -1.0699582e-07 | N4: 9.9150929e-08 | O4: 1.0564701e-08 | P4: 1.3154553e-09 | Q4: -1.0286255e-08 | R4: -1.1867282e-08 | S4: 1.9041307e-08 | T4: -7.9498973e-07 | U4: -1.9145891e-08 | V4: 2.3467607e-07 | W4: -4.4877269e-07 | X4: -7.6375259e-07 | Y4: -4.3819564e-07 | Z4: -1.9009983e-06 | AA4: -9.0018684e-08 | AB4: 9.097626e-08 | AC4: 2.2290034e-07 | AD4: -4.3481962e-08 | AE4: -2.599588e-07 | AF4: 1.3339072e-07 | AG4: -7.731913e-08 | AH4: -6.6420037e-08 | AI4: -1.1931073e-07 | AJ4: -1.8527641e-07 | AK4: 5.264126e-09 | AL4: -2.0755774e-07 | AM4: 3.1811792e-07 | AN4: -4.4164205e-08 | AO4: 1.2343716e-07 | AP4: 3.5604499e-07 | AQ4: -4.4796351e-07 | AR4: -8.5811927e-08 | AS4: 9.0468984e-08 | AT4: 1.1342003e-05
A5: eduHighestC4NaL1 | B5: -0.30605667 | C5: -0.10010041 | D5: 0.00017786664 | E5: -1.2521037e-06 | F5: 0.10422483 | G5: 0.0015114043 | H5: 0.00094837374 | I5: -0.00033176576 | J5: -0.00071788542 | K5: 0.00065476705 | L5: 0.00085726619 | M5: 0.00087478731 | N5: 0.00080280584 | O5: -9.3526241e-06 | P5: -2.3327251e-07 | Q5: -2.6625976e-07 | R5: 1.1426673e-06 | S5: -1.7090848e-05 | T5: -0.00057919005 | U5: -1.8776372e-05 | V5: 0.00024798878 | W5: 0.00051098268 | X5: -0.00016964647 | Y5: -0.0012655487 | Z5: -0.0015178845 | AA5: -2.0105179e-05 | AB5: -3.7058568e-06 | AC5: 0.00026916644 | AD5: 0.00055478879 | AE5: -9.0258816e-05 | AF5: 0.00012132822 | AG5: 0.0001507628 | AH5: 0.00067065892 | AI5: 0.00042791489 | AJ5: 3.1037341e-05 | AK5: 0.00054756624 | AL5: -6.3403992e-07 | AM5: 0.00029759562 | AN5: 1.7075576e-05 | AO5: -0.00022673969 | AP5: -0.00025545485 | AQ5: -0.00017187475 | AR5: -0.0007778984 | AS5: -0.00019761709 | AT5: -0.0061422105
A6: eduHighestC4LowL1 | B6: 0.064428268 | C6: -4.5825734e-05 | D6: 4.128533e-05 | E6: -4.2901867e-07 | F6: 0.0015114043 | G6: 0.0036660541 | H6: 0.0012014725 | I6: -0.00062006023 | J6: -0.0011724919 | K6: 9.2419451e-05 | L6: 0.00049967212 | M6: 0.00047477866 | N6: 0.00048193526 | O6: -2.0767689e-06 | P6: -3.7722708e-06 | Q6: -6.3418991e-06 | R6: -3.1102151e-06 | S6: -1.0448347e-05 | T6: 0.00075749165 | U6: -4.7804132e-06 | V6: 0.00010779726 | W6: 2.0804244e-05 | X6: -0.00035414559 | Y6: 5.3692307e-05 | Z6: -0.00060057793 | AA6: 6.1011174e-05 | AB6: 3.7360974e-05 | AC6: -7.5486766e-05 | AD6: 0.00031781034 | AE6: -0.00037500188 | AF6: -3.6121032e-05 | AG6: -0.00037857593 | AH6: -0.00012125952 | AI6: -0.00010425993 | AJ6: -0.00011883966 | AK6: -0.00021412119 | AL6: 7.8842169e-05 | AM6: -0.00034175915 | AN6: 3.3373256e-05 | AO6: 0.00036086134 | AP6: -0.0002866947 | AQ6: 0.00014513106 | AR6: -0.00056056845 | AS6: -0.00039891611 | AT6: -0.0018441218
A7: eduHighestC4MediumL1 | B7: 0.0765794 | C7: -2.8284519e-05 | D7: 1.3773399e-05 | E7: -1.3403889e-07 | F7: 0.00094837374 | G7: 0.0012014725 | H7: 0.0013012137 | I7: -0.00051188814 | J7: -0.00055294274 | K7: -0.00013800127 | L7: 0.00011991791 | M7: 0.00018475636 | N7: 0.0002155539 | O7: -2.5349727e-06 | P7: -3.155073e-06 | Q7: 4.547761e-06 | R7: -1.1412128e-06 | S7: -3.603704e-06 | T7: 0.00018347511 | U7: -5.6162307e-06 | V7: -4.8919309e-05 | W7: 0.00013703912 | X7: -3.5139839e-06 | Y7: 2.0487142e-05 | Z7: -9.70356e-05 | AA7: 7.9410179e-08 | AB7: 2.0534863e-05 | AC7: -1.7438004e-05 | AD7: 2.6826561e-05 | AE7: -0.00011850257 | AF7: -7.0458742e-06 | AG7: -0.0001191943 | AH7: 8.8260818e-05 | AI7: -2.2620753e-06 | AJ7: -0.000123337 | AK7: -5.1447104e-05 | AL7: -8.56814e-05 | AM7: 4.0038691e-05 | AN7: 2.210399e-05 | AO7: 1.8525528e-05 | AP7: -0.00019569874 | AQ7: 5.9832514e-05 | AR7: -0.00021048494 | AS7: -0.0004634071 | AT7: -0.0010838173
A8: eduHighestPartnerC3MediumL1 | B8: 0.24482281 | C8: 1.387984e-05 | D8: 1.1683099e-05 | E8: -1.4809696e-07 | F8: -0.00033176576 | G8: -0.00062006023 | H8: -0.00051188814 | I8: 0.001456377 | J8: 0.0012303736 | K8: -0.00013997486 | L8: -0.00016629848 | M8: -0.00026687624 | N8: -0.0001249131 | O8: 1.5536715e-06 | P8: 1.2540284e-06 | Q8: 3.2029037e-06 | R8: -1.0042962e-07 | S8: -6.296635e-07 | T8: -0.00038881877 | U8: 1.6643853e-05 | V8: -1.363268e-06 | W8: 1.6818876e-05 | X8: 0.00046079241 | Y8: 3.9939104e-05 | Z8: 0.00034273537 | AA8: 7.1073314e-05 | AB8: -7.0975804e-05 | AC8: -0.00030372124 | AD8: -0.00027462765 | AE8: -0.00020315364 | AF8: -0.00038289816 | AG8: -0.00027185085 | AH8: -0.00053807095 | AI8: -0.00038290804 | AJ8: -0.00039488527 | AK8: -0.00033229925 | AL8: -0.00048501057 | AM8: -0.00029984899 | AN8: 2.4413412e-05 | AO8: -2.5707949e-05 | AP8: -0.00021329505 | AQ8: -7.0581294e-05 | AR8: 0.00017785638 | AS8: 0.0005122952 | AT8: -0.0015638058
A9: eduHighestPartnerC3LowL1 | B9: 0.27635231 | C9: 2.9652325e-05 | D9: -7.7545908e-06 | E9: -8.5580014e-08 | F9: -0.00071788542 | G9: -0.0011724919 | H9: -0.00055294274 | I9: 0.0012303736 | J9: 0.0027855585 | K9: 6.9393741e-06 | L9: 1.453802e-05 | M9: -0.00023721741 | N9: -2.4667055e-05 | O9: 8.2203908e-06 | P9: -2.2418609e-07 | Q9: 1.8216471e-05 | R9: 4.6597835e-06 | S9: -1.0832661e-06 | T9: -0.00063810593 | U9: 2.396796e-05 | V9: 5.0435699e-05 | W9: 0.00013313099 | X9: 0.00050712137 | Y9: 7.2659698e-05 | Z9: 0.00086970303 | AA9: 8.1056634e-05 | AB9: -7.204697e-05 | AC9: -0.00034026931 | AD9: -0.00043898863 | AE9: -0.00032711844 | AF9: -0.00041261926 | AG9: 5.0523352e-05 | AH9: -0.00056548351 | AI9: -0.00036046501 | AJ9: -0.0002543728 | AK9: -0.00035708108 | AL9: -0.00051819173 | AM9: -0.00015829615 | AN9: 4.1127229e-05 | AO9: -3.0778736e-05 | AP9: -0.00018605144 | AQ9: -0.00034025695 | AR9: 0.00055056546 | AS9: 0.0002705857 | AT9: -0.0027156125
A10: healthSelfRatedFairL1 | B10: 0.1449211 | C10: -0.00059286479 | D10: -7.4104129e-06 | E10: 1.5851457e-07 | F10: 0.00065476705 | G10: 9.2419451e-05 | H10: -0.00013800127 | I10: -0.00013997486 | J10: 6.9393741e-06 | K10: 0.0071249716 | L10: 0.0068295009 | M10: 0.0072960977 | N10: 0.0074564592 | O10: -6.7243795e-05 | P10: -3.2632186e-05 | Q10: 1.3892916e-05 | R10: -4.6773048e-06 | S10: -9.3831153e-07 | T10: -6.4642853e-06 | U10: -3.1017841e-05 | V10: 0.00014069263 | W10: -0.00015708193 | X10: -0.00086157033 | Y10: -0.00022646348 | Z10: -0.00018621767 | AA10: -8.0112223e-05 | AB10: 0.0001064997 | AC10: -0.00011906334 | AD10: 0.00021481512 | AE10: -0.0010427582 | AF10: -2.9302892e-05 | AG10: 2.0618337e-05 | AH10: 5.9196101e-05 | AI10: -0.0001320559 | AJ10: 0.0002596841 | AK10: -5.0021881e-05 | AL10: 7.2887756e-05 | AM10: -0.00033948698 | AN10: -4.3108475e-05 | AO10: 0.000187255 | AP10: 0.00050303619 | AQ10: 1.6027e-05 | AR10: -7.0042998e-06 | AS10: 0.00018800305 | AT10: -0.00096502767
A11: healthSelfRatedGoodL1 | B11: 0.17396464 | C11: -0.00070526099 | D11: 7.841343e-06 | E11: 7.7646234e-08 | F11: 0.00085726619 | G11: 0.00049967212 | H11: 0.00011991791 | I11: -0.00016629848 | J11: 1.453802e-05 | K11: 0.0068295009 | L11: 0.0093951244 | M11: 0.0096635259 | N11: 0.010030196 | O11: -0.00012693845 | P11: -6.27967e-05 | Q11: 1.5156875e-05 | R11: -9.3916964e-06 | S11: -8.278835e-06 | T11: 5.6394062e-05 | U11: -3.0315407e-05 | V11: 9.5776649e-05 | W11: -0.0001135103 | X11: -0.0013326562 | Y11: -0.00027197014 | Z11: -0.00071087773 | AA11: -0.00014757317 | AB11: 0.00014893879 | AC11: -0.00051137332 | AD11: 0.00022142328 | AE11: -0.0013199667 | AF11: -0.00044525265 | AG11: -0.00032865594 | AH11: -0.0002955736 | AI11: -0.0005655217 | AJ11: -3.2872486e-05 | AK11: -0.00047779185 | AL11: -0.00024230542 | AM11: -0.00075094329 | AN11: 2.9949361e-06 | AO11: 0.00030506509 | AP11: 0.00024588975 | AQ11: -0.00030432229 | AR11: -0.00011949274 | AS11: -0.00041838182 | AT11: 0.0012421896
A12: healthSelfRatedVeryGoodL1 | B12: 0.21576151 | C12: -0.00014204087 | D12: 3.248267e-05 | E12: -1.0699582e-07 | F12: 0.00087478731 | G12: 0.00047477866 | H12: 0.00018475636 | I12: -0.00026687624 | J12: -0.00023721741 | K12: 0.0072960977 | L12: 0.0096635259 | M12: 0.011396534 | N12: 0.011359105 | O12: -0.0001639085 | P12: -7.9496199e-05 | Q12: 1.8727834e-05 | R12: -1.5511763e-05 | S12: -1.0534891e-05 | T12: 1.9071671e-05 | U12: -4.0050028e-05 | V12: 1.5585721e-05 | W12: -0.0001310151 | X12: -0.001025976 | Y12: -0.00034289905 | Z12: -0.0008880552 | AA12: -0.00014559527 | AB12: 0.00013139279 | AC12: -0.00031663639 | AD12: 0.00012347502 | AE12: -0.001129942 | AF12: -0.00028004489 | AG12: -0.00051725738 | AH12: -6.3288648e-05 | AI12: -0.00043254359 | AJ12: 2.8221821e-05 | AK12: -0.00029745123 | AL12: -9.5650526e-05 | AM12: -0.00064082365 | AN12: -5.3020809e-06 | AO12: 0.00019081023 | AP12: 0.00039613545 | AQ12: -0.00012829284 | AR12: -0.00012016096 | AS12: -0.00061807204 | AT12: 0.0025299769
A13: healthSelfRatedExcellentL1 | B13: 0.2527093 | C13: -0.00040179766 | D13: 1.2796493e-05 | E13: 9.9150929e-08 | F13: 0.00080280584 | G13: 0.00048193526 | H13: 0.0002155539 | I13: -0.0001249131 | J13: -2.4667055e-05 | K13: 0.0074564592 | L13: 0.010030196 | M13: 0.011359105 | N13: 0.013283907 | O13: -0.0001733317 | P13: -8.7279638e-05 | Q13: 1.9181392e-05 | R13: -1.2880901e-05 | S13: -1.2541017e-05 | T13: -7.5465635e-05 | U13: -4.5369596e-05 | V13: 2.4177582e-05 | W13: -0.00022994552 | X13: -0.0012211204 | Y13: -0.00019162038 | Z13: -0.0010353858 | AA13: -0.00015787287 | AB13: 0.00013715089 | AC13: -0.00044225821 | AD13: 5.8327373e-05 | AE13: -0.0010240597 | AF13: -0.00043931485 | AG13: -0.00068261179 | AH13: -0.00025490574 | AI13: -0.00059435228 | AJ13: -0.00011039277 | AK13: -0.0005119023 | AL13: -0.00039966928 | AM13: -0.00044859949 | AN13: 2.3310868e-05 | AO13: 6.2784335e-05 | AP13: 0.00011498531 | AQ13: -0.0002724292 | AR13: -0.00014425678 | AS13: -0.00066666504 | AT13: 0.0029365658
